2021-12-20 22:02:10,116 ERROR: Exception on /edit_grade [GET] [in /home/anastasiia/.local/lib/python3.8/site-packages/flask/app.py:1457]
Traceback (most recent call last):
  File "/home/anastasiia/.local/lib/python3.8/site-packages/flask/app.py", line 2073, in wsgi_app
    response = self.full_dispatch_request()
  File "/home/anastasiia/.local/lib/python3.8/site-packages/flask/app.py", line 1518, in full_dispatch_request
    rv = self.handle_user_exception(e)
  File "/home/anastasiia/.local/lib/python3.8/site-packages/flask/app.py", line 1516, in full_dispatch_request
    rv = self.dispatch_request()
  File "/home/anastasiia/.local/lib/python3.8/site-packages/flask/app.py", line 1502, in dispatch_request
    return self.ensure_sync(self.view_functions[rule.endpoint])(**req.view_args)
  File "/home/anastasiia/.local/lib/python3.8/site-packages/flask_login/utils.py", line 272, in decorated_view
    return func(*args, **kwargs)
  File "/home/anastasiia/projects/softserve_internship/flask_app/app/routes.py", line 204, in edit_grade
    return render_template('edit_grade.html', title='Edit Grade', form=form)
  File "/home/anastasiia/.local/lib/python3.8/site-packages/flask/templating.py", line 147, in render_template
    return _render(
  File "/home/anastasiia/.local/lib/python3.8/site-packages/flask/templating.py", line 128, in _render
    rv = template.render(context)
  File "/home/anastasiia/.local/lib/python3.8/site-packages/jinja2/environment.py", line 1291, in render
    self.environment.handle_exception()
  File "/home/anastasiia/.local/lib/python3.8/site-packages/jinja2/environment.py", line 925, in handle_exception
    raise rewrite_traceback_stack(source=source)
  File "/home/anastasiia/projects/softserve_internship/flask_app/app/templates/edit_grade.html", line 1, in top-level template code
    {% extends "base.html" %}
  File "/home/anastasiia/projects/softserve_internship/flask_app/app/templates/base.html", line 35, in top-level template code
    {% block content %}{% endblock %}
  File "/home/anastasiia/projects/softserve_internship/flask_app/app/templates/edit_grade.html", line 8, in block 'content'
    {{ form.interview.label }}<br>
  File "/home/anastasiia/.local/lib/python3.8/site-packages/jinja2/environment.py", line 474, in getattr
    return getattr(obj, attribute)
jinja2.exceptions.UndefinedError: 'app.forms.EditGradeForm object' has no attribute 'interview'
2021-12-20 22:02:58,446 INFO: Microblog startup [in /home/anastasiia/projects/softserve_internship/flask_app/app/__init__.py:47]
2021-12-20 22:04:44,001 INFO: Microblog startup [in /home/anastasiia/projects/softserve_internship/flask_app/app/__init__.py:47]
2021-12-20 22:05:00,390 INFO: Microblog startup [in /home/anastasiia/projects/softserve_internship/flask_app/app/__init__.py:47]
2021-12-20 22:05:12,762 ERROR: Exception on /edit_grade/5 [GET] [in /home/anastasiia/.local/lib/python3.8/site-packages/flask/app.py:1457]
Traceback (most recent call last):
  File "/home/anastasiia/.local/lib/python3.8/site-packages/flask/app.py", line 2073, in wsgi_app
    response = self.full_dispatch_request()
  File "/home/anastasiia/.local/lib/python3.8/site-packages/flask/app.py", line 1518, in full_dispatch_request
    rv = self.handle_user_exception(e)
  File "/home/anastasiia/.local/lib/python3.8/site-packages/flask/app.py", line 1516, in full_dispatch_request
    rv = self.dispatch_request()
  File "/home/anastasiia/.local/lib/python3.8/site-packages/flask/app.py", line 1502, in dispatch_request
    return self.ensure_sync(self.view_functions[rule.endpoint])(**req.view_args)
  File "/home/anastasiia/.local/lib/python3.8/site-packages/flask_login/utils.py", line 272, in decorated_view
    return func(*args, **kwargs)
  File "/home/anastasiia/projects/softserve_internship/flask_app/app/routes.py", line 204, in edit_grade
    form.grade.data = g.grade
AttributeError: 'NoneType' object has no attribute 'grade'
2021-12-20 22:05:44,248 INFO: Microblog startup [in /home/anastasiia/projects/softserve_internship/flask_app/app/__init__.py:47]
2021-12-20 22:05:46,264 ERROR: Exception on /edit_grade/5 [GET] [in /home/anastasiia/.local/lib/python3.8/site-packages/flask/app.py:1457]
Traceback (most recent call last):
  File "/home/anastasiia/.local/lib/python3.8/site-packages/flask/app.py", line 2073, in wsgi_app
    response = self.full_dispatch_request()
  File "/home/anastasiia/.local/lib/python3.8/site-packages/flask/app.py", line 1518, in full_dispatch_request
    rv = self.handle_user_exception(e)
  File "/home/anastasiia/.local/lib/python3.8/site-packages/flask/app.py", line 1516, in full_dispatch_request
    rv = self.dispatch_request()
  File "/home/anastasiia/.local/lib/python3.8/site-packages/flask/app.py", line 1502, in dispatch_request
    return self.ensure_sync(self.view_functions[rule.endpoint])(**req.view_args)
  File "/home/anastasiia/.local/lib/python3.8/site-packages/flask_login/utils.py", line 272, in decorated_view
    return func(*args, **kwargs)
  File "/home/anastasiia/projects/softserve_internship/flask_app/app/routes.py", line 205, in edit_grade
    form.grade.data = g.grade
AttributeError: 'NoneType' object has no attribute 'grade'
2021-12-20 22:06:15,470 INFO: Microblog startup [in /home/anastasiia/projects/softserve_internship/flask_app/app/__init__.py:47]
2021-12-20 22:06:18,819 ERROR: Exception on /edit_grade/5 [GET] [in /home/anastasiia/.local/lib/python3.8/site-packages/flask/app.py:1457]
Traceback (most recent call last):
  File "/home/anastasiia/.local/lib/python3.8/site-packages/flask/app.py", line 2073, in wsgi_app
    response = self.full_dispatch_request()
  File "/home/anastasiia/.local/lib/python3.8/site-packages/flask/app.py", line 1518, in full_dispatch_request
    rv = self.handle_user_exception(e)
  File "/home/anastasiia/.local/lib/python3.8/site-packages/flask/app.py", line 1516, in full_dispatch_request
    rv = self.dispatch_request()
  File "/home/anastasiia/.local/lib/python3.8/site-packages/flask/app.py", line 1502, in dispatch_request
    return self.ensure_sync(self.view_functions[rule.endpoint])(**req.view_args)
  File "/home/anastasiia/.local/lib/python3.8/site-packages/flask_login/utils.py", line 272, in decorated_view
    return func(*args, **kwargs)
  File "/home/anastasiia/projects/softserve_internship/flask_app/app/routes.py", line 206, in edit_grade
    form.interviewers.data = g.interviews
AttributeError: 'Grade' object has no attribute 'interviews'
2021-12-20 22:06:56,904 INFO: Microblog startup [in /home/anastasiia/projects/softserve_internship/flask_app/app/__init__.py:47]
2021-12-20 22:06:58,550 ERROR: Exception on /edit_grade/5 [GET] [in /home/anastasiia/.local/lib/python3.8/site-packages/flask/app.py:1457]
Traceback (most recent call last):
  File "/home/anastasiia/.local/lib/python3.8/site-packages/flask/app.py", line 2073, in wsgi_app
    response = self.full_dispatch_request()
  File "/home/anastasiia/.local/lib/python3.8/site-packages/flask/app.py", line 1518, in full_dispatch_request
    rv = self.handle_user_exception(e)
  File "/home/anastasiia/.local/lib/python3.8/site-packages/flask/app.py", line 1516, in full_dispatch_request
    rv = self.dispatch_request()
  File "/home/anastasiia/.local/lib/python3.8/site-packages/flask/app.py", line 1502, in dispatch_request
    return self.ensure_sync(self.view_functions[rule.endpoint])(**req.view_args)
  File "/home/anastasiia/.local/lib/python3.8/site-packages/flask_login/utils.py", line 272, in decorated_view
    return func(*args, **kwargs)
  File "/home/anastasiia/projects/softserve_internship/flask_app/app/routes.py", line 206, in edit_grade
    form.interviewers.data = g.interviewers
AttributeError: 'Grade' object has no attribute 'interviewers'
2021-12-20 22:08:07,867 INFO: Microblog startup [in /home/anastasiia/projects/softserve_internship/flask_app/app/__init__.py:47]
2021-12-20 22:08:25,263 INFO: Microblog startup [in /home/anastasiia/projects/softserve_internship/flask_app/app/__init__.py:47]
2021-12-20 22:10:13,842 INFO: Microblog startup [in /home/anastasiia/projects/softserve_internship/flask_app/app/__init__.py:47]
2021-12-20 22:13:45,324 INFO: Microblog startup [in /home/anastasiia/projects/softserve_internship/flask_app/app/__init__.py:47]
2021-12-20 22:16:38,743 INFO: Microblog startup [in /home/anastasiia/projects/softserve_internship/flask_app/app/__init__.py:47]
2021-12-20 22:17:22,650 INFO: Microblog startup [in /home/anastasiia/projects/softserve_internship/flask_app/app/__init__.py:47]
2021-12-20 22:28:01,605 INFO: Microblog startup [in /home/anastasiia/projects/softserve_internship/flask_app/app/__init__.py:47]
2021-12-20 22:31:40,465 INFO: Microblog startup [in /home/anastasiia/projects/softserve_internship/flask_app/app/__init__.py:47]
2021-12-20 22:32:37,255 ERROR: Exception on /add_interview [POST] [in /home/anastasiia/.local/lib/python3.8/site-packages/flask/app.py:1457]
Traceback (most recent call last):
  File "/home/anastasiia/.local/lib/python3.8/site-packages/flask/app.py", line 2073, in wsgi_app
    response = self.full_dispatch_request()
  File "/home/anastasiia/.local/lib/python3.8/site-packages/flask/app.py", line 1518, in full_dispatch_request
    rv = self.handle_user_exception(e)
  File "/home/anastasiia/.local/lib/python3.8/site-packages/flask/app.py", line 1516, in full_dispatch_request
    rv = self.dispatch_request()
  File "/home/anastasiia/.local/lib/python3.8/site-packages/flask/app.py", line 1502, in dispatch_request
    return self.ensure_sync(self.view_functions[rule.endpoint])(**req.view_args)
  File "/home/anastasiia/.local/lib/python3.8/site-packages/flask_login/utils.py", line 272, in decorated_view
    return func(*args, **kwargs)
  File "/home/anastasiia/projects/softserve_internship/flask_app/app/routes.py", line 224, in add_interview
    final_grade = sum(list(map(int, form.questions.data))) / len(form.interviewers.data) / (len(form.questions.data) * Question.query.filter_by(Question.max_grade).first())
TypeError: filter_by() takes 1 positional argument but 2 were given
2021-12-20 22:33:23,943 INFO: Microblog startup [in /home/anastasiia/projects/softserve_internship/flask_app/app/__init__.py:47]
