2021-12-20 22:50:01,147 ERROR: Exception on /add_interview [POST] [in /home/anastasiia/.local/lib/python3.8/site-packages/flask/app.py:1457]
Traceback (most recent call last):
  File "/home/anastasiia/.local/lib/python3.8/site-packages/flask/app.py", line 2073, in wsgi_app
    response = self.full_dispatch_request()
  File "/home/anastasiia/.local/lib/python3.8/site-packages/flask/app.py", line 1518, in full_dispatch_request
    rv = self.handle_user_exception(e)
  File "/home/anastasiia/.local/lib/python3.8/site-packages/flask/app.py", line 1516, in full_dispatch_request
    rv = self.dispatch_request()
  File "/home/anastasiia/.local/lib/python3.8/site-packages/flask/app.py", line 1502, in dispatch_request
    return self.ensure_sync(self.view_functions[rule.endpoint])(**req.view_args)
  File "/home/anastasiia/.local/lib/python3.8/site-packages/flask_login/utils.py", line 272, in decorated_view
    return func(*args, **kwargs)
  File "/home/anastasiia/projects/softserve_internship/flask_app/app/routes.py", line 224, in add_interview
    final_grade = sum(list(map(int, form.questions.data))) / len(form.interviewers.data) / (len(form.questions.data) * max([max_grade for max_grade in form.questions.data]))
TypeError: unsupported operand type(s) for /: 'float' and 'str'
2021-12-20 22:51:55,437 INFO: Microblog startup [in /home/anastasiia/projects/softserve_internship/flask_app/app/__init__.py:47]
2021-12-20 23:17:24,404 INFO: Microblog startup [in /home/anastasiia/projects/softserve_internship/flask_app/app/__init__.py:47]
2021-12-20 23:17:58,180 INFO: Microblog startup [in /home/anastasiia/projects/softserve_internship/flask_app/app/__init__.py:47]
2021-12-20 23:19:42,481 INFO: Microblog startup [in /home/anastasiia/projects/softserve_internship/flask_app/app/__init__.py:47]
2021-12-20 23:31:52,809 INFO: Microblog startup [in /home/anastasiia/projects/softserve_internship/flask_app/app/__init__.py:47]
2021-12-20 23:33:40,586 INFO: Microblog startup [in /home/anastasiia/projects/softserve_internship/flask_app/app/__init__.py:47]
2021-12-20 23:34:44,702 INFO: Microblog startup [in /home/anastasiia/projects/softserve_internship/flask_app/app/__init__.py:47]
2021-12-20 23:41:10,505 INFO: Microblog startup [in /home/anastasiia/projects/softserve_internship/flask_app/app/__init__.py:47]
2021-12-20 23:41:17,487 ERROR: Exception on /edit_grade/5 [GET] [in /home/anastasiia/.local/lib/python3.8/site-packages/flask/app.py:1457]
Traceback (most recent call last):
  File "/home/anastasiia/.local/lib/python3.8/site-packages/sqlalchemy/util/_collections.py", line 1008, in __call__
    return self.registry[key]
KeyError: <greenlet.greenlet object at 0x7f26ac7e7e00 (otid=0x7f26ad0dab40) current active started main>

During handling of the above exception, another exception occurred:

Traceback (most recent call last):
  File "/home/anastasiia/.local/lib/python3.8/site-packages/flask/app.py", line 2073, in wsgi_app
    response = self.full_dispatch_request()
  File "/home/anastasiia/.local/lib/python3.8/site-packages/flask/app.py", line 1518, in full_dispatch_request
    rv = self.handle_user_exception(e)
  File "/home/anastasiia/.local/lib/python3.8/site-packages/flask/app.py", line 1514, in full_dispatch_request
    rv = self.preprocess_request()
  File "/home/anastasiia/.local/lib/python3.8/site-packages/flask/app.py", line 1857, in preprocess_request
    rv = self.ensure_sync(before_func)()
  File "/home/anastasiia/projects/softserve_internship/flask_app/app/routes.py", line 14, in before_request
    if current_user.is_authenticated:
  File "/home/anastasiia/.local/lib/python3.8/site-packages/werkzeug/local.py", line 432, in __get__
    obj = instance._get_current_object()
  File "/home/anastasiia/.local/lib/python3.8/site-packages/werkzeug/local.py", line 554, in _get_current_object
    return self.__local()  # type: ignore
  File "/home/anastasiia/.local/lib/python3.8/site-packages/flask_login/utils.py", line 26, in <lambda>
    current_user = LocalProxy(lambda: _get_user())
  File "/home/anastasiia/.local/lib/python3.8/site-packages/flask_login/utils.py", line 346, in _get_user
    current_app.login_manager._load_user()
  File "/home/anastasiia/.local/lib/python3.8/site-packages/flask_login/login_manager.py", line 318, in _load_user
    user = self._user_callback(user_id)
  File "/home/anastasiia/projects/softserve_internship/flask_app/app/models.py", line 64, in load_user
    return User.query.get(int(id))
  File "/home/anastasiia/.local/lib/python3.8/site-packages/flask_sqlalchemy/__init__.py", line 552, in __get__
    return type.query_class(mapper, session=self.sa.session())
  File "/home/anastasiia/.local/lib/python3.8/site-packages/sqlalchemy/orm/scoping.py", line 47, in __call__
    sess = self.registry()
  File "/home/anastasiia/.local/lib/python3.8/site-packages/sqlalchemy/util/_collections.py", line 1010, in __call__
    return self.registry.setdefault(key, self.createfunc())
  File "/home/anastasiia/.local/lib/python3.8/site-packages/sqlalchemy/orm/session.py", line 4180, in __call__
    return self.class_(**local_kw)
  File "/home/anastasiia/.local/lib/python3.8/site-packages/flask_sqlalchemy/__init__.py", line 176, in __init__
    bind = options.pop('bind', None) or db.engine
  File "/home/anastasiia/.local/lib/python3.8/site-packages/flask_sqlalchemy/__init__.py", line 998, in engine
    return self.get_engine()
  File "/home/anastasiia/.local/lib/python3.8/site-packages/flask_sqlalchemy/__init__.py", line 1017, in get_engine
    return connector.get_engine()
  File "/home/anastasiia/.local/lib/python3.8/site-packages/flask_sqlalchemy/__init__.py", line 593, in get_engine
    sa_url, options = self.get_options(sa_url, echo)
  File "/home/anastasiia/.local/lib/python3.8/site-packages/flask_sqlalchemy/__init__.py", line 608, in get_options
    sa_url, options = self._sa.apply_driver_hacks(self._app, sa_url, options)
  File "/home/anastasiia/.local/lib/python3.8/site-packages/flask_sqlalchemy/__init__.py", line 933, in apply_driver_hacks
    if sa_url.drivername.startswith('mysql'):
AttributeError: 'NoneType' object has no attribute 'drivername'
2021-12-20 23:42:17,226 INFO: Microblog startup [in /home/anastasiia/projects/softserve_internship/flask_app/app/__init__.py:47]
2021-12-20 23:50:28,663 INFO: Microblog startup [in /home/anastasiia/projects/softserve_internship/flask_app/app/__init__.py:47]
2021-12-20 23:51:21,157 INFO: Microblog startup [in /home/anastasiia/projects/softserve_internship/flask_app/app/__init__.py:47]
2021-12-20 23:53:16,426 INFO: Microblog startup [in /home/anastasiia/projects/softserve_internship/flask_app/app/__init__.py:47]
2021-12-20 23:55:48,900 INFO: Microblog startup [in /home/anastasiia/projects/softserve_internship/flask_app/app/__init__.py:47]
2021-12-21 00:00:09,340 INFO: Microblog startup [in /home/anastasiia/projects/softserve_internship/flask_app/app/__init__.py:47]
2021-12-21 00:01:52,746 INFO: Microblog startup [in /home/anastasiia/projects/softserve_internship/flask_app/app/__init__.py:47]
2021-12-21 00:10:35,778 INFO: Microblog startup [in /home/anastasiia/projects/softserve_internship/flask_app/app/__init__.py:47]
2021-12-21 00:11:18,273 INFO: Microblog startup [in /home/anastasiia/projects/softserve_internship/flask_app/app/__init__.py:47]
2021-12-21 09:29:43,026 INFO: Microblog startup [in /home/anastasiia/projects/softserve_internship/flask_app/app/__init__.py:47]
2021-12-21 09:29:47,360 ERROR: Exception on /edit_grade/11 [POST] [in /home/anastasiia/.local/lib/python3.8/site-packages/flask/app.py:1457]
Traceback (most recent call last):
  File "/home/anastasiia/.local/lib/python3.8/site-packages/flask/app.py", line 2073, in wsgi_app
    response = self.full_dispatch_request()
  File "/home/anastasiia/.local/lib/python3.8/site-packages/flask/app.py", line 1518, in full_dispatch_request
    rv = self.handle_user_exception(e)
  File "/home/anastasiia/.local/lib/python3.8/site-packages/flask/app.py", line 1516, in full_dispatch_request
    rv = self.dispatch_request()
  File "/home/anastasiia/.local/lib/python3.8/site-packages/flask/app.py", line 1502, in dispatch_request
    return self.ensure_sync(self.view_functions[rule.endpoint])(**req.view_args)
  File "/home/anastasiia/.local/lib/python3.8/site-packages/flask_login/utils.py", line 272, in decorated_view
    return func(*args, **kwargs)
  File "/home/anastasiia/projects/softserve_internship/flask_app/app/routes.py", line 195, in edit_grade
    if form.validate_on_submit():
  File "/home/anastasiia/.local/lib/python3.8/site-packages/flask_wtf/form.py", line 86, in validate_on_submit
    return self.is_submitted() and self.validate()
  File "/home/anastasiia/.local/lib/python3.8/site-packages/wtforms/form.py", line 329, in validate
    return super().validate(extra)
  File "/home/anastasiia/.local/lib/python3.8/site-packages/wtforms/form.py", line 146, in validate
    if not field.validate(self, extra):
  File "/home/anastasiia/.local/lib/python3.8/site-packages/wtforms/fields/core.py", line 231, in validate
    self.pre_validate(form)
  File "/home/anastasiia/.local/lib/python3.8/site-packages/wtforms/fields/choices.py", line 136, in pre_validate
    raise TypeError(self.gettext("Choices cannot be None."))
TypeError: Choices cannot be None.
