2021-12-27 10:01:14,617 INFO: Microblog startup [in /home/anastasiia/projects/softserve_internship/flask_app/app/__init__.py:47]
2021-12-27 10:01:49,860 INFO: Microblog startup [in /home/anastasiia/projects/softserve_internship/flask_app/app/__init__.py:47]
2021-12-27 10:01:58,742 INFO: Microblog startup [in /home/anastasiia/projects/softserve_internship/flask_app/app/__init__.py:47]
2021-12-27 11:27:49,859 INFO: Microblog startup [in /home/anastasiia/projects/softserve_internship/flask_app/app/__init__.py:53]
2021-12-27 11:28:12,346 INFO: Microblog startup [in /home/anastasiia/projects/softserve_internship/flask_app/app/__init__.py:53]
2021-12-27 11:28:19,003 INFO: Microblog startup [in /home/anastasiia/projects/softserve_internship/flask_app/app/__init__.py:53]
2021-12-27 11:29:58,660 INFO: Microblog startup [in /home/anastasiia/projects/softserve_internship/flask_app/app/__init__.py:53]
2021-12-27 11:30:50,879 INFO: Microblog startup [in /home/anastasiia/projects/softserve_internship/flask_app/app/__init__.py:53]
2021-12-27 11:30:53,185 INFO: Microblog startup [in /home/anastasiia/projects/softserve_internship/flask_app/app/__init__.py:53]
2021-12-27 11:31:07,714 INFO: Microblog startup [in /home/anastasiia/projects/softserve_internship/flask_app/app/__init__.py:53]
2021-12-27 11:31:17,830 INFO: Microblog startup [in /home/anastasiia/projects/softserve_internship/flask_app/app/__init__.py:53]
2021-12-27 11:31:30,093 INFO: Microblog startup [in /home/anastasiia/projects/softserve_internship/flask_app/app/__init__.py:53]
2021-12-27 11:54:12,738 INFO: Microblog startup [in /home/anastasiia/projects/softserve_internship/flask_app/app/__init__.py:53]
2021-12-27 11:57:06,664 INFO: Microblog startup [in /home/anastasiia/projects/softserve_internship/flask_app/app/__init__.py:53]
2021-12-27 12:04:22,272 INFO: Microblog startup [in /home/anastasiia/projects/softserve_internship/flask_app/app/__init__.py:53]
2021-12-27 12:04:26,451 ERROR: Exception on /index [GET] [in /home/anastasiia/.local/lib/python3.8/site-packages/flask/app.py:1457]
Traceback (most recent call last):
  File "/home/anastasiia/.local/lib/python3.8/site-packages/flask/app.py", line 2073, in wsgi_app
    response = self.full_dispatch_request()
  File "/home/anastasiia/.local/lib/python3.8/site-packages/flask/app.py", line 1518, in full_dispatch_request
    rv = self.handle_user_exception(e)
  File "/home/anastasiia/.local/lib/python3.8/site-packages/flask/app.py", line 1516, in full_dispatch_request
    rv = self.dispatch_request()
  File "/home/anastasiia/.local/lib/python3.8/site-packages/flask/app.py", line 1502, in dispatch_request
    return self.ensure_sync(self.view_functions[rule.endpoint])(**req.view_args)
  File "/home/anastasiia/.local/lib/python3.8/site-packages/flask_login/utils.py", line 271, in decorated_view
    return current_app.login_manager.unauthorized()
  File "/home/anastasiia/.local/lib/python3.8/site-packages/flask_login/login_manager.py", line 150, in unauthorized
    return self.unauthorized_callback()
  File "/home/anastasiia/projects/softserve_internship/flask_app/app/routes.py", line 53, in unauthorized_callback
    return redirect(url_for('login'))
  File "/home/anastasiia/.local/lib/python3.8/site-packages/flask/helpers.py", line 338, in url_for
    return appctx.app.handle_url_build_error(error, endpoint, values)
  File "/home/anastasiia/.local/lib/python3.8/site-packages/flask/helpers.py", line 325, in url_for
    rv = url_adapter.build(
  File "/home/anastasiia/.local/lib/python3.8/site-packages/werkzeug/routing.py", line 2314, in build
    raise BuildError(endpoint, values, method, self)
werkzeug.routing.BuildError: Could not build url for endpoint 'login'. Did you mean 'logout' instead?
2021-12-27 12:05:05,816 INFO: Microblog startup [in /home/anastasiia/projects/softserve_internship/flask_app/app/__init__.py:53]
2021-12-27 12:07:27,760 INFO: Microblog startup [in /home/anastasiia/projects/softserve_internship/flask_app/app/__init__.py:53]
2021-12-27 12:07:33,912 ERROR: Exception on /index [GET] [in /home/anastasiia/.local/lib/python3.8/site-packages/flask/app.py:1457]
Traceback (most recent call last):
  File "/home/anastasiia/.local/lib/python3.8/site-packages/flask/app.py", line 2073, in wsgi_app
    response = self.full_dispatch_request()
  File "/home/anastasiia/.local/lib/python3.8/site-packages/flask/app.py", line 1518, in full_dispatch_request
    rv = self.handle_user_exception(e)
  File "/home/anastasiia/.local/lib/python3.8/site-packages/flask/app.py", line 1516, in full_dispatch_request
    rv = self.dispatch_request()
  File "/home/anastasiia/.local/lib/python3.8/site-packages/flask/app.py", line 1502, in dispatch_request
    return self.ensure_sync(self.view_functions[rule.endpoint])(**req.view_args)
  File "/home/anastasiia/.local/lib/python3.8/site-packages/flask_login/utils.py", line 271, in decorated_view
    return current_app.login_manager.unauthorized()
  File "/home/anastasiia/.local/lib/python3.8/site-packages/flask_login/login_manager.py", line 150, in unauthorized
    return self.unauthorized_callback()
  File "/home/anastasiia/projects/softserve_internship/flask_app/app/routes.py", line 53, in unauthorized_callback
    return redirect(url_for('login'))
  File "/home/anastasiia/.local/lib/python3.8/site-packages/flask/helpers.py", line 338, in url_for
    return appctx.app.handle_url_build_error(error, endpoint, values)
  File "/home/anastasiia/.local/lib/python3.8/site-packages/flask/helpers.py", line 325, in url_for
    rv = url_adapter.build(
  File "/home/anastasiia/.local/lib/python3.8/site-packages/werkzeug/routing.py", line 2314, in build
    raise BuildError(endpoint, values, method, self)
werkzeug.routing.BuildError: Could not build url for endpoint 'login'. Did you mean 'login_route' instead?
2021-12-27 12:07:36,204 ERROR: Exception on / [GET] [in /home/anastasiia/.local/lib/python3.8/site-packages/flask/app.py:1457]
Traceback (most recent call last):
  File "/home/anastasiia/.local/lib/python3.8/site-packages/flask/app.py", line 2073, in wsgi_app
    response = self.full_dispatch_request()
  File "/home/anastasiia/.local/lib/python3.8/site-packages/flask/app.py", line 1518, in full_dispatch_request
    rv = self.handle_user_exception(e)
  File "/home/anastasiia/.local/lib/python3.8/site-packages/flask/app.py", line 1516, in full_dispatch_request
    rv = self.dispatch_request()
  File "/home/anastasiia/.local/lib/python3.8/site-packages/flask/app.py", line 1502, in dispatch_request
    return self.ensure_sync(self.view_functions[rule.endpoint])(**req.view_args)
  File "/home/anastasiia/.local/lib/python3.8/site-packages/flask_login/utils.py", line 271, in decorated_view
    return current_app.login_manager.unauthorized()
  File "/home/anastasiia/.local/lib/python3.8/site-packages/flask_login/login_manager.py", line 150, in unauthorized
    return self.unauthorized_callback()
  File "/home/anastasiia/projects/softserve_internship/flask_app/app/routes.py", line 53, in unauthorized_callback
    return redirect(url_for('login'))
  File "/home/anastasiia/.local/lib/python3.8/site-packages/flask/helpers.py", line 338, in url_for
    return appctx.app.handle_url_build_error(error, endpoint, values)
  File "/home/anastasiia/.local/lib/python3.8/site-packages/flask/helpers.py", line 325, in url_for
    rv = url_adapter.build(
  File "/home/anastasiia/.local/lib/python3.8/site-packages/werkzeug/routing.py", line 2314, in build
    raise BuildError(endpoint, values, method, self)
werkzeug.routing.BuildError: Could not build url for endpoint 'login'. Did you mean 'login_route' instead?
2021-12-27 12:08:11,382 INFO: Microblog startup [in /home/anastasiia/projects/softserve_internship/flask_app/app/__init__.py:53]
