2021-12-20 09:56:12,929 ERROR: Exception on /add_user [GET] [in /home/anastasiia/.local/lib/python3.8/site-packages/flask/app.py:1457]
Traceback (most recent call last):
  File "/home/anastasiia/.local/lib/python3.8/site-packages/flask/app.py", line 2073, in wsgi_app
    response = self.full_dispatch_request()
  File "/home/anastasiia/.local/lib/python3.8/site-packages/flask/app.py", line 1518, in full_dispatch_request
    rv = self.handle_user_exception(e)
  File "/home/anastasiia/.local/lib/python3.8/site-packages/flask/app.py", line 1516, in full_dispatch_request
    rv = self.dispatch_request()
  File "/home/anastasiia/.local/lib/python3.8/site-packages/flask/app.py", line 1502, in dispatch_request
    return self.ensure_sync(self.view_functions[rule.endpoint])(**req.view_args)
  File "/home/anastasiia/projects/softserve_internship/flask_app/app/routes.py", line 77, in add_user
    return render_template('add_user', form=form)
  File "/home/anastasiia/.local/lib/python3.8/site-packages/flask/templating.py", line 148, in render_template
    ctx.app.jinja_env.get_or_select_template(template_name_or_list),
  File "/home/anastasiia/.local/lib/python3.8/site-packages/jinja2/environment.py", line 1068, in get_or_select_template
    return self.get_template(template_name_or_list, parent, globals)
  File "/home/anastasiia/.local/lib/python3.8/site-packages/jinja2/environment.py", line 997, in get_template
    return self._load_template(name, globals)
  File "/home/anastasiia/.local/lib/python3.8/site-packages/jinja2/environment.py", line 958, in _load_template
    template = self.loader.load(self, name, self.make_globals(globals))
  File "/home/anastasiia/.local/lib/python3.8/site-packages/jinja2/loaders.py", line 125, in load
    source, filename, uptodate = self.get_source(environment, name)
  File "/home/anastasiia/.local/lib/python3.8/site-packages/flask/templating.py", line 59, in get_source
    return self._get_source_fast(environment, template)
  File "/home/anastasiia/.local/lib/python3.8/site-packages/flask/templating.py", line 95, in _get_source_fast
    raise TemplateNotFound(template)
jinja2.exceptions.TemplateNotFound: add_user
2021-12-20 09:57:47,361 INFO: Microblog startup [in /home/anastasiia/projects/softserve_internship/flask_app/app/__init__.py:47]
2021-12-20 09:57:52,171 ERROR: Exception on /add_user [GET] [in /home/anastasiia/.local/lib/python3.8/site-packages/flask/app.py:1457]
Traceback (most recent call last):
  File "/home/anastasiia/.local/lib/python3.8/site-packages/flask/app.py", line 2073, in wsgi_app
    response = self.full_dispatch_request()
  File "/home/anastasiia/.local/lib/python3.8/site-packages/flask/app.py", line 1518, in full_dispatch_request
    rv = self.handle_user_exception(e)
  File "/home/anastasiia/.local/lib/python3.8/site-packages/flask/app.py", line 1516, in full_dispatch_request
    rv = self.dispatch_request()
  File "/home/anastasiia/.local/lib/python3.8/site-packages/flask/app.py", line 1502, in dispatch_request
    return self.ensure_sync(self.view_functions[rule.endpoint])(**req.view_args)
  File "/home/anastasiia/projects/softserve_internship/flask_app/app/routes.py", line 77, in add_user
    return render_template('add_user', form=form)
  File "/home/anastasiia/.local/lib/python3.8/site-packages/flask/templating.py", line 148, in render_template
    ctx.app.jinja_env.get_or_select_template(template_name_or_list),
  File "/home/anastasiia/.local/lib/python3.8/site-packages/jinja2/environment.py", line 1068, in get_or_select_template
    return self.get_template(template_name_or_list, parent, globals)
  File "/home/anastasiia/.local/lib/python3.8/site-packages/jinja2/environment.py", line 997, in get_template
    return self._load_template(name, globals)
  File "/home/anastasiia/.local/lib/python3.8/site-packages/jinja2/environment.py", line 958, in _load_template
    template = self.loader.load(self, name, self.make_globals(globals))
  File "/home/anastasiia/.local/lib/python3.8/site-packages/jinja2/loaders.py", line 125, in load
    source, filename, uptodate = self.get_source(environment, name)
  File "/home/anastasiia/.local/lib/python3.8/site-packages/flask/templating.py", line 59, in get_source
    return self._get_source_fast(environment, template)
  File "/home/anastasiia/.local/lib/python3.8/site-packages/flask/templating.py", line 95, in _get_source_fast
    raise TemplateNotFound(template)
jinja2.exceptions.TemplateNotFound: add_user
2021-12-20 09:58:33,699 INFO: Microblog startup [in /home/anastasiia/projects/softserve_internship/flask_app/app/__init__.py:47]
2021-12-20 09:58:37,601 ERROR: Exception on /add_user [GET] [in /home/anastasiia/.local/lib/python3.8/site-packages/flask/app.py:1457]
Traceback (most recent call last):
  File "/home/anastasiia/.local/lib/python3.8/site-packages/flask/app.py", line 2073, in wsgi_app
    response = self.full_dispatch_request()
  File "/home/anastasiia/.local/lib/python3.8/site-packages/flask/app.py", line 1518, in full_dispatch_request
    rv = self.handle_user_exception(e)
  File "/home/anastasiia/.local/lib/python3.8/site-packages/flask/app.py", line 1516, in full_dispatch_request
    rv = self.dispatch_request()
  File "/home/anastasiia/.local/lib/python3.8/site-packages/flask/app.py", line 1502, in dispatch_request
    return self.ensure_sync(self.view_functions[rule.endpoint])(**req.view_args)
  File "/home/anastasiia/projects/softserve_internship/flask_app/app/routes.py", line 77, in add_user
    return render_template('add_user.html', form=form)
  File "/home/anastasiia/.local/lib/python3.8/site-packages/flask/templating.py", line 147, in render_template
    return _render(
  File "/home/anastasiia/.local/lib/python3.8/site-packages/flask/templating.py", line 128, in _render
    rv = template.render(context)
  File "/home/anastasiia/.local/lib/python3.8/site-packages/jinja2/environment.py", line 1291, in render
    self.environment.handle_exception()
  File "/home/anastasiia/.local/lib/python3.8/site-packages/jinja2/environment.py", line 925, in handle_exception
    raise rewrite_traceback_stack(source=source)
  File "/home/anastasiia/projects/softserve_internship/flask_app/app/templates/add_user.html", line 1, in top-level template code
    {% extends "base.html" %}
  File "/home/anastasiia/projects/softserve_internship/flask_app/app/templates/base.html", line 35, in top-level template code
    {% block content %}{% endblock %}
  File "/home/anastasiia/projects/softserve_internship/flask_app/app/templates/add_user.html", line 9, in block 'content'
    {{ form.interview_id(size=32) }}<br>
  File "/home/anastasiia/.local/lib/python3.8/site-packages/jinja2/utils.py", line 84, in from_obj
    if hasattr(obj, "jinja_pass_arg"):
jinja2.exceptions.UndefinedError: 'app.forms.UserFrom object' has no attribute 'interview_id'
2021-12-20 09:59:32,700 INFO: Microblog startup [in /home/anastasiia/projects/softserve_internship/flask_app/app/__init__.py:47]
2021-12-20 12:32:37,706 INFO: Microblog startup [in /home/anastasiia/projects/softserve_internship/flask_app/app/__init__.py:47]
2021-12-20 12:34:01,103 INFO: Microblog startup [in /home/anastasiia/projects/softserve_internship/flask_app/app/__init__.py:47]
2021-12-20 12:34:54,274 INFO: Microblog startup [in /home/anastasiia/projects/softserve_internship/flask_app/app/__init__.py:47]
2021-12-20 12:36:24,871 INFO: Microblog startup [in /home/anastasiia/projects/softserve_internship/flask_app/app/__init__.py:47]
2021-12-20 12:36:37,523 ERROR: Exception on /add_grade [GET] [in /home/anastasiia/.local/lib/python3.8/site-packages/flask/app.py:1457]
Traceback (most recent call last):
  File "/home/anastasiia/.local/lib/python3.8/site-packages/flask/app.py", line 2073, in wsgi_app
    response = self.full_dispatch_request()
  File "/home/anastasiia/.local/lib/python3.8/site-packages/flask/app.py", line 1518, in full_dispatch_request
    rv = self.handle_user_exception(e)
  File "/home/anastasiia/.local/lib/python3.8/site-packages/flask/app.py", line 1516, in full_dispatch_request
    rv = self.dispatch_request()
  File "/home/anastasiia/.local/lib/python3.8/site-packages/flask/app.py", line 1502, in dispatch_request
    return self.ensure_sync(self.view_functions[rule.endpoint])(**req.view_args)
  File "/home/anastasiia/.local/lib/python3.8/site-packages/flask_login/utils.py", line 272, in decorated_view
    return func(*args, **kwargs)
  File "/home/anastasiia/projects/softserve_internship/flask_app/app/routes.py", line 172, in add_grade
    return render_template('add_grade.html', title='Grade', form=form)
  File "/home/anastasiia/.local/lib/python3.8/site-packages/flask/templating.py", line 147, in render_template
    return _render(
  File "/home/anastasiia/.local/lib/python3.8/site-packages/flask/templating.py", line 128, in _render
    rv = template.render(context)
  File "/home/anastasiia/.local/lib/python3.8/site-packages/jinja2/environment.py", line 1291, in render
    self.environment.handle_exception()
  File "/home/anastasiia/.local/lib/python3.8/site-packages/jinja2/environment.py", line 925, in handle_exception
    raise rewrite_traceback_stack(source=source)
  File "/home/anastasiia/projects/softserve_internship/flask_app/app/templates/add_grade.html", line 1, in top-level template code
    {% extends "base.html" %}
  File "/home/anastasiia/projects/softserve_internship/flask_app/app/templates/base.html", line 35, in top-level template code
    {% block content %}{% endblock %}
  File "/home/anastasiia/projects/softserve_internship/flask_app/app/templates/add_grade.html", line 8, in block 'content'
    {{ form.interview.label }}<br>
  File "/home/anastasiia/.local/lib/python3.8/site-packages/jinja2/environment.py", line 474, in getattr
    return getattr(obj, attribute)
jinja2.exceptions.UndefinedError: 'app.forms.GradeForm object' has no attribute 'interview'
2021-12-20 12:40:14,651 INFO: Microblog startup [in /home/anastasiia/projects/softserve_internship/flask_app/app/__init__.py:47]
