2021-12-21 18:03:29,032 ERROR: Exception on /edit_grade/6 [GET] [in /home/anastasiia/.local/lib/python3.8/site-packages/flask/app.py:1457]
Traceback (most recent call last):
  File "/home/anastasiia/.local/lib/python3.8/site-packages/flask/app.py", line 2073, in wsgi_app
    response = self.full_dispatch_request()
  File "/home/anastasiia/.local/lib/python3.8/site-packages/flask/app.py", line 1518, in full_dispatch_request
    rv = self.handle_user_exception(e)
  File "/home/anastasiia/.local/lib/python3.8/site-packages/flask/app.py", line 1516, in full_dispatch_request
    rv = self.dispatch_request()
  File "/home/anastasiia/.local/lib/python3.8/site-packages/flask/app.py", line 1502, in dispatch_request
    return self.ensure_sync(self.view_functions[rule.endpoint])(**req.view_args)
  File "/home/anastasiia/.local/lib/python3.8/site-packages/flask_login/utils.py", line 272, in decorated_view
    return func(*args, **kwargs)
  File "/home/anastasiia/projects/softserve_internship/flask_app/app/routes.py", line 228, in edit_grade
    form.interviewers.default = g.interviewer
AttributeError: 'list' object has no attribute 'default'
2021-12-21 18:03:49,767 INFO: Microblog startup [in /home/anastasiia/projects/softserve_internship/flask_app/app/__init__.py:47]
2021-12-21 18:03:53,559 ERROR: Exception on /edit_grade/6 [GET] [in /home/anastasiia/.local/lib/python3.8/site-packages/flask/app.py:1457]
Traceback (most recent call last):
  File "/home/anastasiia/.local/lib/python3.8/site-packages/flask/app.py", line 2073, in wsgi_app
    response = self.full_dispatch_request()
  File "/home/anastasiia/.local/lib/python3.8/site-packages/flask/app.py", line 1518, in full_dispatch_request
    rv = self.handle_user_exception(e)
  File "/home/anastasiia/.local/lib/python3.8/site-packages/flask/app.py", line 1516, in full_dispatch_request
    rv = self.dispatch_request()
  File "/home/anastasiia/.local/lib/python3.8/site-packages/flask/app.py", line 1502, in dispatch_request
    return self.ensure_sync(self.view_functions[rule.endpoint])(**req.view_args)
  File "/home/anastasiia/.local/lib/python3.8/site-packages/flask_login/utils.py", line 272, in decorated_view
    return func(*args, **kwargs)
  File "/home/anastasiia/projects/softserve_internship/flask_app/app/routes.py", line 240, in edit_grade
    return render_template('edit_grade.html', title='Edit Grade', form=form)
  File "/home/anastasiia/.local/lib/python3.8/site-packages/flask/templating.py", line 147, in render_template
    return _render(
  File "/home/anastasiia/.local/lib/python3.8/site-packages/flask/templating.py", line 128, in _render
    rv = template.render(context)
  File "/home/anastasiia/.local/lib/python3.8/site-packages/jinja2/environment.py", line 1291, in render
    self.environment.handle_exception()
  File "/home/anastasiia/.local/lib/python3.8/site-packages/jinja2/environment.py", line 925, in handle_exception
    raise rewrite_traceback_stack(source=source)
  File "/home/anastasiia/projects/softserve_internship/flask_app/app/templates/edit_grade.html", line 1, in top-level template code
    {% extends "base.html" %}
  File "/home/anastasiia/projects/softserve_internship/flask_app/app/templates/base.html", line 35, in top-level template code
    {% block content %}{% endblock %}
  File "/home/anastasiia/projects/softserve_internship/flask_app/app/templates/edit_grade.html", line 16, in block 'content'
    {{ form.interviewers(cols=50, rows=4) }}<br>
TypeError: 'list' object is not callable
2021-12-21 18:04:36,765 INFO: Microblog startup [in /home/anastasiia/projects/softserve_internship/flask_app/app/__init__.py:47]
2021-12-21 18:06:29,476 INFO: Microblog startup [in /home/anastasiia/projects/softserve_internship/flask_app/app/__init__.py:47]
2021-12-21 18:06:43,087 ERROR: Exception on /edit_grade/6 [POST] [in /home/anastasiia/.local/lib/python3.8/site-packages/flask/app.py:1457]
Traceback (most recent call last):
  File "/home/anastasiia/.local/lib/python3.8/site-packages/flask/app.py", line 2073, in wsgi_app
    response = self.full_dispatch_request()
  File "/home/anastasiia/.local/lib/python3.8/site-packages/flask/app.py", line 1518, in full_dispatch_request
    rv = self.handle_user_exception(e)
  File "/home/anastasiia/.local/lib/python3.8/site-packages/flask/app.py", line 1516, in full_dispatch_request
    rv = self.dispatch_request()
  File "/home/anastasiia/.local/lib/python3.8/site-packages/flask/app.py", line 1502, in dispatch_request
    return self.ensure_sync(self.view_functions[rule.endpoint])(**req.view_args)
  File "/home/anastasiia/.local/lib/python3.8/site-packages/flask_login/utils.py", line 272, in decorated_view
    return func(*args, **kwargs)
  File "/home/anastasiia/projects/softserve_internship/flask_app/app/routes.py", line 218, in edit_grade
    if form.validate_on_submit():
  File "/home/anastasiia/.local/lib/python3.8/site-packages/flask_wtf/form.py", line 86, in validate_on_submit
    return self.is_submitted() and self.validate()
  File "/home/anastasiia/.local/lib/python3.8/site-packages/wtforms/form.py", line 329, in validate
    return super().validate(extra)
  File "/home/anastasiia/.local/lib/python3.8/site-packages/wtforms/form.py", line 146, in validate
    if not field.validate(self, extra):
  File "/home/anastasiia/.local/lib/python3.8/site-packages/wtforms/fields/core.py", line 231, in validate
    self.pre_validate(form)
  File "/home/anastasiia/.local/lib/python3.8/site-packages/wtforms/fields/choices.py", line 136, in pre_validate
    raise TypeError(self.gettext("Choices cannot be None."))
TypeError: Choices cannot be None.
2021-12-21 18:25:20,356 INFO: Microblog startup [in /home/anastasiia/projects/softserve_internship/flask_app/app/__init__.py:47]
2021-12-21 18:25:32,961 ERROR: Exception on /edit_grade/5 [POST] [in /home/anastasiia/.local/lib/python3.8/site-packages/flask/app.py:1457]
Traceback (most recent call last):
  File "/home/anastasiia/.local/lib/python3.8/site-packages/flask/app.py", line 2073, in wsgi_app
    response = self.full_dispatch_request()
  File "/home/anastasiia/.local/lib/python3.8/site-packages/flask/app.py", line 1518, in full_dispatch_request
    rv = self.handle_user_exception(e)
  File "/home/anastasiia/.local/lib/python3.8/site-packages/flask/app.py", line 1516, in full_dispatch_request
    rv = self.dispatch_request()
  File "/home/anastasiia/.local/lib/python3.8/site-packages/flask/app.py", line 1502, in dispatch_request
    return self.ensure_sync(self.view_functions[rule.endpoint])(**req.view_args)
  File "/home/anastasiia/.local/lib/python3.8/site-packages/flask_login/utils.py", line 272, in decorated_view
    return func(*args, **kwargs)
  File "/home/anastasiia/projects/softserve_internship/flask_app/app/routes.py", line 218, in edit_grade
    if form.validate_on_submit():
  File "/home/anastasiia/.local/lib/python3.8/site-packages/flask_wtf/form.py", line 86, in validate_on_submit
    return self.is_submitted() and self.validate()
  File "/home/anastasiia/.local/lib/python3.8/site-packages/wtforms/form.py", line 329, in validate
    return super().validate(extra)
  File "/home/anastasiia/.local/lib/python3.8/site-packages/wtforms/form.py", line 146, in validate
    if not field.validate(self, extra):
  File "/home/anastasiia/.local/lib/python3.8/site-packages/wtforms/fields/core.py", line 231, in validate
    self.pre_validate(form)
  File "/home/anastasiia/.local/lib/python3.8/site-packages/wtforms/fields/choices.py", line 136, in pre_validate
    raise TypeError(self.gettext("Choices cannot be None."))
TypeError: Choices cannot be None.
2021-12-21 18:40:38,008 INFO: Microblog startup [in /home/anastasiia/projects/softserve_internship/flask_app/app/__init__.py:47]
2021-12-21 18:40:48,122 ERROR: Exception on /edit_grade/5 [GET] [in /home/anastasiia/.local/lib/python3.8/site-packages/flask/app.py:1457]
Traceback (most recent call last):
  File "/home/anastasiia/.local/lib/python3.8/site-packages/flask/app.py", line 2073, in wsgi_app
    response = self.full_dispatch_request()
  File "/home/anastasiia/.local/lib/python3.8/site-packages/flask/app.py", line 1518, in full_dispatch_request
    rv = self.handle_user_exception(e)
  File "/home/anastasiia/.local/lib/python3.8/site-packages/flask/app.py", line 1516, in full_dispatch_request
    rv = self.dispatch_request()
  File "/home/anastasiia/.local/lib/python3.8/site-packages/flask/app.py", line 1502, in dispatch_request
    return self.ensure_sync(self.view_functions[rule.endpoint])(**req.view_args)
  File "/home/anastasiia/.local/lib/python3.8/site-packages/flask_login/utils.py", line 272, in decorated_view
    return func(*args, **kwargs)
  File "/home/anastasiia/projects/softserve_internship/flask_app/app/routes.py", line 227, in edit_grade
    form.interviewers.choices = User.query.filter_by(grades=id).first()
  File "/home/anastasiia/.local/lib/python3.8/site-packages/sqlalchemy/orm/query.py", line 1793, in filter_by
    clauses = [
  File "/home/anastasiia/.local/lib/python3.8/site-packages/sqlalchemy/orm/query.py", line 1794, in <listcomp>
    _entity_namespace_key(from_entity, key) == value
  File "/home/anastasiia/.local/lib/python3.8/site-packages/sqlalchemy/sql/operators.py", line 360, in __eq__
    return self.operate(eq, other)
  File "/home/anastasiia/.local/lib/python3.8/site-packages/sqlalchemy/orm/attributes.py", line 317, in operate
    return op(self.comparator, *other, **kwargs)
  File "/home/anastasiia/.local/lib/python3.8/site-packages/sqlalchemy/orm/relationships.py", line 1311, in __eq__
    raise sa_exc.InvalidRequestError(
sqlalchemy.exc.InvalidRequestError: Can't compare a collection to an object or collection; use contains() to test for membership.
2021-12-21 18:41:50,233 INFO: Microblog startup [in /home/anastasiia/projects/softserve_internship/flask_app/app/__init__.py:47]
2021-12-21 18:44:47,868 INFO: Microblog startup [in /home/anastasiia/projects/softserve_internship/flask_app/app/__init__.py:47]
