2021-12-20 14:22:06,060 ERROR: Exception on /interviews [GET] [in /home/anastasiia/.local/lib/python3.8/site-packages/flask/app.py:1457]
Traceback (most recent call last):
  File "/home/anastasiia/.local/lib/python3.8/site-packages/flask/app.py", line 2073, in wsgi_app
    response = self.full_dispatch_request()
  File "/home/anastasiia/.local/lib/python3.8/site-packages/flask/app.py", line 1518, in full_dispatch_request
    rv = self.handle_user_exception(e)
  File "/home/anastasiia/.local/lib/python3.8/site-packages/flask/app.py", line 1516, in full_dispatch_request
    rv = self.dispatch_request()
  File "/home/anastasiia/.local/lib/python3.8/site-packages/flask/app.py", line 1502, in dispatch_request
    return self.ensure_sync(self.view_functions[rule.endpoint])(**req.view_args)
  File "/home/anastasiia/.local/lib/python3.8/site-packages/flask_login/utils.py", line 272, in decorated_view
    return func(*args, **kwargs)
  File "/home/anastasiia/projects/softserve_internship/flask_app/app/routes.py", line 241, in interviews
    return render_template('interviews.html', title='Interviews', inws=inws)
  File "/home/anastasiia/.local/lib/python3.8/site-packages/flask/templating.py", line 147, in render_template
    return _render(
  File "/home/anastasiia/.local/lib/python3.8/site-packages/flask/templating.py", line 128, in _render
    rv = template.render(context)
  File "/home/anastasiia/.local/lib/python3.8/site-packages/jinja2/environment.py", line 1291, in render
    self.environment.handle_exception()
  File "/home/anastasiia/.local/lib/python3.8/site-packages/jinja2/environment.py", line 925, in handle_exception
    raise rewrite_traceback_stack(source=source)
  File "/home/anastasiia/projects/softserve_internship/flask_app/app/templates/interviews.html", line 1, in top-level template code
    {% extends "base.html" %}
  File "/home/anastasiia/projects/softserve_internship/flask_app/app/templates/base.html", line 35, in top-level template code
    {% block content %}{% endblock %}
  File "/home/anastasiia/projects/softserve_internship/flask_app/app/templates/interviews.html", line 18, in block 'content'
    <p><a href="{{ url_for('edit_interview') }}">Edit interview</a></p>
  File "/home/anastasiia/.local/lib/python3.8/site-packages/flask/helpers.py", line 338, in url_for
    return appctx.app.handle_url_build_error(error, endpoint, values)
  File "/home/anastasiia/.local/lib/python3.8/site-packages/flask/helpers.py", line 325, in url_for
    rv = url_adapter.build(
  File "/home/anastasiia/.local/lib/python3.8/site-packages/werkzeug/routing.py", line 2314, in build
    raise BuildError(endpoint, values, method, self)
werkzeug.routing.BuildError: Could not build url for endpoint 'edit_interview'. Did you mean 'add_interview' instead?
2021-12-20 14:22:37,697 ERROR: Exception on /interviews [GET] [in /home/anastasiia/.local/lib/python3.8/site-packages/flask/app.py:1457]
Traceback (most recent call last):
  File "/home/anastasiia/.local/lib/python3.8/site-packages/flask/app.py", line 2073, in wsgi_app
    response = self.full_dispatch_request()
  File "/home/anastasiia/.local/lib/python3.8/site-packages/flask/app.py", line 1518, in full_dispatch_request
    rv = self.handle_user_exception(e)
  File "/home/anastasiia/.local/lib/python3.8/site-packages/flask/app.py", line 1516, in full_dispatch_request
    rv = self.dispatch_request()
  File "/home/anastasiia/.local/lib/python3.8/site-packages/flask/app.py", line 1502, in dispatch_request
    return self.ensure_sync(self.view_functions[rule.endpoint])(**req.view_args)
  File "/home/anastasiia/.local/lib/python3.8/site-packages/flask_login/utils.py", line 272, in decorated_view
    return func(*args, **kwargs)
  File "/home/anastasiia/projects/softserve_internship/flask_app/app/routes.py", line 241, in interviews
    return render_template('interviews.html', title='Interviews', inws=inws)
  File "/home/anastasiia/.local/lib/python3.8/site-packages/flask/templating.py", line 147, in render_template
    return _render(
  File "/home/anastasiia/.local/lib/python3.8/site-packages/flask/templating.py", line 128, in _render
    rv = template.render(context)
  File "/home/anastasiia/.local/lib/python3.8/site-packages/jinja2/environment.py", line 1291, in render
    self.environment.handle_exception()
  File "/home/anastasiia/.local/lib/python3.8/site-packages/jinja2/environment.py", line 925, in handle_exception
    raise rewrite_traceback_stack(source=source)
  File "/home/anastasiia/projects/softserve_internship/flask_app/app/templates/interviews.html", line 1, in top-level template code
    {% extends "base.html" %}
  File "/home/anastasiia/projects/softserve_internship/flask_app/app/templates/base.html", line 35, in top-level template code
    {% block content %}{% endblock %}
  File "/home/anastasiia/projects/softserve_internship/flask_app/app/templates/interviews.html", line 18, in block 'content'
    {% if interview == request.form %}
  File "/home/anastasiia/.local/lib/python3.8/site-packages/flask/helpers.py", line 338, in url_for
    return appctx.app.handle_url_build_error(error, endpoint, values)
  File "/home/anastasiia/.local/lib/python3.8/site-packages/flask/helpers.py", line 325, in url_for
    rv = url_adapter.build(
  File "/home/anastasiia/.local/lib/python3.8/site-packages/werkzeug/routing.py", line 2314, in build
    raise BuildError(endpoint, values, method, self)
werkzeug.routing.BuildError: Could not build url for endpoint 'edit_interview'. Did you mean 'add_interview' instead?
2021-12-20 14:22:41,813 INFO: Microblog startup [in /home/anastasiia/projects/softserve_internship/flask_app/app/__init__.py:47]
2021-12-20 14:25:09,495 INFO: Microblog startup [in /home/anastasiia/projects/softserve_internship/flask_app/app/__init__.py:47]
2021-12-20 14:26:43,598 INFO: Microblog startup [in /home/anastasiia/projects/softserve_internship/flask_app/app/__init__.py:47]
2021-12-20 14:27:16,138 ERROR: Exception on /grade/11 [GET] [in /home/anastasiia/.local/lib/python3.8/site-packages/flask/app.py:1457]
Traceback (most recent call last):
  File "/home/anastasiia/.local/lib/python3.8/site-packages/flask/app.py", line 2073, in wsgi_app
    response = self.full_dispatch_request()
  File "/home/anastasiia/.local/lib/python3.8/site-packages/flask/app.py", line 1518, in full_dispatch_request
    rv = self.handle_user_exception(e)
  File "/home/anastasiia/.local/lib/python3.8/site-packages/flask/app.py", line 1516, in full_dispatch_request
    rv = self.dispatch_request()
  File "/home/anastasiia/.local/lib/python3.8/site-packages/flask/app.py", line 1502, in dispatch_request
    return self.ensure_sync(self.view_functions[rule.endpoint])(**req.view_args)
  File "/home/anastasiia/.local/lib/python3.8/site-packages/flask_login/utils.py", line 272, in decorated_view
    return func(*args, **kwargs)
  File "/home/anastasiia/projects/softserve_internship/flask_app/app/routes.py", line 187, in grade
    return render_template('grade.html', grade=g)
  File "/home/anastasiia/.local/lib/python3.8/site-packages/flask/templating.py", line 147, in render_template
    return _render(
  File "/home/anastasiia/.local/lib/python3.8/site-packages/flask/templating.py", line 128, in _render
    rv = template.render(context)
  File "/home/anastasiia/.local/lib/python3.8/site-packages/jinja2/environment.py", line 1291, in render
    self.environment.handle_exception()
  File "/home/anastasiia/.local/lib/python3.8/site-packages/jinja2/environment.py", line 925, in handle_exception
    raise rewrite_traceback_stack(source=source)
  File "/home/anastasiia/projects/softserve_internship/flask_app/app/templates/grade.html", line 1, in top-level template code
    {% extends "base.html" %}
  File "/home/anastasiia/projects/softserve_internship/flask_app/app/templates/base.html", line 35, in top-level template code
    {% block content %}{% endblock %}
  File "/home/anastasiia/projects/softserve_internship/flask_app/app/templates/grade.html", line 12, in block 'content'
    <p><a href="{{ url_for('edit_grade') }}">Edit grade</a></p>
  File "/home/anastasiia/.local/lib/python3.8/site-packages/flask/helpers.py", line 338, in url_for
    return appctx.app.handle_url_build_error(error, endpoint, values)
  File "/home/anastasiia/.local/lib/python3.8/site-packages/flask/helpers.py", line 325, in url_for
    rv = url_adapter.build(
  File "/home/anastasiia/.local/lib/python3.8/site-packages/werkzeug/routing.py", line 2314, in build
    raise BuildError(endpoint, values, method, self)
werkzeug.routing.BuildError: Could not build url for endpoint 'edit_grade'. Did you forget to specify values ['id']?
2021-12-20 14:27:44,704 INFO: Microblog startup [in /home/anastasiia/projects/softserve_internship/flask_app/app/__init__.py:47]
